<?xml version="1.0" ?>
<!-- =================================================================================== -->
<!-- |    This document was autogenerated by xacro from src/wall-e/urdf/robot.urdf.xacro | -->
<!-- |    EDITING THIS FILE BY HAND IS NOT RECOMMENDED                                 | -->
<!-- =================================================================================== -->
<robot name="robot_urdf">
  <!-- Base Link -->
  <link name="base_link">
    <inertial>
      <origin rpy="0 0 0" xyz="1.7528E-07 4.3368E-18 -3.1564E-07"/>
      <mass value="0.45937"/>
      <inertia ixx="0.00043611" ixy="-4.0945E-20" ixz="-2.1354E-20" iyy="0.00088919" iyz="1.6285E-22" izz="0.0012573"/>
    </inertial>
    <visual>
      <origin rpy="0 0 0" xyz="0 0 0"/>
      <geometry>
        <mesh filename="package://wall-e/meshes/base_link.STL"/>
      </geometry>
      <material name="">
        <color rgba="0.79216 0.81961 0.93333 1"/>
      </material>
    </visual>
    <collision>
      <origin rpy="0 0 0" xyz="0 0 0"/>
      <geometry>
        <mesh filename="package://wall-e/meshes/base_link.STL"/>
      </geometry>
    </collision>
  </link>
  <link name="lf_link">
    <inertial>
      <origin rpy="0 0 0" xyz="-1.1319E-06 0.00085532 2.8562E-06"/>
      <mass value="0.033011"/>
      <inertia ixx="6.6258e-06" ixy="3.0204e-10" ixz="-5.6054e-12" iyy="1.1308e-05" iyz="-7.6739e-10" izz="6.6258e-06"/>
    </inertial>
    <visual>
      <origin rpy="0 0 0" xyz="0 0 0"/>
      <geometry>
        <mesh filename="package://wall-e/meshes/lf_link.STL"/>
      </geometry>
      <material name="">
        <color rgba="0.79216 0.81961 0.93333 1"/>
      </material>
    </visual>
    <collision>
      <origin rpy="0 0 0" xyz="0 0 0"/>
      <geometry>
        <mesh filename="package://wall-e/meshes/lf_link.STL"/>
      </geometry>
    </collision>
  </link>
  <link name="lb_link">
    <inertial>
      <origin rpy="0 0 0" xyz="2.51E-06 0.00085532 1.7718E-06"/>
      <mass value="0.033011"/>
      <inertia ixx="6.6258e-06" ixy="-6.7485e-10" ixz="7.8844e-12" iyy="1.1308e-05" iyz="-4.7403e-10" izz="6.6258e-06"/>
    </inertial>
    <visual>
      <origin rpy="0 0 0" xyz="0 0 0"/>
      <geometry>
        <mesh filename="package://wall-e/meshes/lb_link.STL"/>
      </geometry>
      <material name="">
        <color rgba="0.79216 0.81961 0.93333 1"/>
      </material>
    </visual>
    <collision>
      <origin rpy="0 0 0" xyz="0 0 0"/>
      <geometry>
        <mesh filename="package://wall-e/meshes/lb_link.STL"/>
      </geometry>
    </collision>
  </link>
  <link name="rf_link">
    <inertial>
      <origin rpy="0 0 0" xyz="-1.8104E-06 -0.00085532 2.4825E-06"/>
      <mass value="0.033011"/>
      <inertia ixx="6.6258e-06" ixy="-4.8757e-10" ixz="-8.202e-12" iyy="1.1308e-05" iyz="6.6517e-10" izz="6.6258e-06"/>
    </inertial>
    <visual>
      <origin rpy="0 0 0" xyz="0 0 0"/>
      <geometry>
        <mesh filename="package://wall-e/meshes/rf_link.STL"/>
      </geometry>
      <material name="">
        <color rgba="0.79216 0.81961 0.93333 1"/>
      </material>
    </visual>
    <collision>
      <origin rpy="0 0 0" xyz="0 0 0"/>
      <geometry>
        <mesh filename="package://wall-e/meshes/rf_link.STL"/>
      </geometry>
    </collision>
  </link>
  <link name="rb_link">
    <inertial>
      <origin rpy="0 0 0" xyz="-2.7058E-06 -0.00085532 -1.4556E-06"/>
      <mass value="0.033011"/>
      <inertia ixx="6.6258e-06" ixy="-7.2536e-10" ixz="7.3893e-12" iyy="1.1308e-05" iyz="-3.9246e-10" izz="6.6258e-06"/>
    </inertial>
    <visual>
      <origin rpy="0 0 0" xyz="0 0 0"/>
      <geometry>
        <mesh filename="package://wall-e/meshes/rb_link.STL"/>
      </geometry>
      <material name="">
        <color rgba="0.79216 0.81961 0.93333 1"/>
      </material>
    </visual>
    <collision>
      <origin rpy="0 0 0" xyz="0 0 0"/>
      <geometry>
        <mesh filename="package://wall-e/meshes/rb_link.STL"/>
      </geometry>
    </collision>
  </link>
  <!-- Joints -->
  <joint name="lf_joint" type="continuous">
    <origin rpy="0 0 0" xyz="0.035 0.06 0"/>
    <parent link="base_link"/>
    <child link="lf_link"/>
    <axis xyz="0 1 0"/>
  </joint>
  <joint name="lb_joint" type="continuous">
    <origin rpy="0 0 0" xyz="-0.035 0.06 0"/>
    <parent link="base_link"/>
    <child link="lb_link"/>
    <axis xyz="0 1 0"/>
  </joint>
  <joint name="rf_joint" type="continuous">
    <origin rpy="0 0 0" xyz="0.035 -0.06 0"/>
    <parent link="base_link"/>
    <child link="rf_link"/>
    <axis xyz="0 1 0"/>
  </joint>
  <joint name="rb_joint" type="continuous">
    <origin rpy="0 0 0" xyz="-0.035 -0.06 0"/>
    <parent link="base_link"/>
    <child link="rb_link"/>
    <axis xyz="0 1 0"/>
  </joint>
  <plugin filename="diff_drive_controller" name="gz::sim::systems::DiffDrive">
    <left_joint>lf_joint</left_joint>
    <right_joint>rf_joint</right_joint>
    <wheel_separation>0.12</wheel_separation>
    <wheel_radius>0.1</wheel_radius>
    <max_linear_acceleration>0.5</max_linear_acceleration>
    <topic>cmd_vel</topic>
    <odom_topic>odom</odom_topic>
    <frame_id>odom</frame_id>
    <child_frame_id>base_link</child_frame_id>
    <odom_publisher_frequency>30</odom_publisher_frequency>
    <tf_topic>/tf</tf_topic>
  </plugin>
</robot>
